2019-03-13 20:18:40,511 ERROR: Exception on /reset_password_request [POST] [in /Users/shaquillewyanque/git/microblog/venv/lib/python3.7/site-packages/flask/app.py:1761]
Traceback (most recent call last):
  File "/Users/shaquillewyanque/git/microblog/venv/lib/python3.7/site-packages/flask/app.py", line 2292, in wsgi_app
    response = self.full_dispatch_request()
  File "/Users/shaquillewyanque/git/microblog/venv/lib/python3.7/site-packages/flask/app.py", line 1815, in full_dispatch_request
    rv = self.handle_user_exception(e)
  File "/Users/shaquillewyanque/git/microblog/venv/lib/python3.7/site-packages/flask/app.py", line 1718, in handle_user_exception
    reraise(exc_type, exc_value, tb)
  File "/Users/shaquillewyanque/git/microblog/venv/lib/python3.7/site-packages/flask/_compat.py", line 35, in reraise
    raise value
  File "/Users/shaquillewyanque/git/microblog/venv/lib/python3.7/site-packages/flask/app.py", line 1813, in full_dispatch_request
    rv = self.dispatch_request()
  File "/Users/shaquillewyanque/git/microblog/venv/lib/python3.7/site-packages/flask/app.py", line 1799, in dispatch_request
    return self.view_functions[rule.endpoint](**req.view_args)
  File "/Users/shaquillewyanque/git/microblog/app/routes.py", line 141, in reset_password_request
    send_password_reset_email(user)
  File "/Users/shaquillewyanque/git/microblog/app/email.py", line 16, in send_password_reset_email
    text_body=render_template('email/reset_password.txt', user=user, token=token),
  File "/Users/shaquillewyanque/git/microblog/venv/lib/python3.7/site-packages/flask/templating.py", line 135, in render_template
    context, ctx.app)
  File "/Users/shaquillewyanque/git/microblog/venv/lib/python3.7/site-packages/flask/templating.py", line 117, in _render
    rv = template.render(context)
  File "/Users/shaquillewyanque/git/microblog/venv/lib/python3.7/site-packages/jinja2/asyncsupport.py", line 76, in render
    return original_render(self, *args, **kwargs)
  File "/Users/shaquillewyanque/git/microblog/venv/lib/python3.7/site-packages/jinja2/environment.py", line 1008, in render
    return self.environment.handle_exception(exc_info, True)
  File "/Users/shaquillewyanque/git/microblog/venv/lib/python3.7/site-packages/jinja2/environment.py", line 780, in handle_exception
    reraise(exc_type, exc_value, tb)
  File "/Users/shaquillewyanque/git/microblog/venv/lib/python3.7/site-packages/jinja2/_compat.py", line 37, in reraise
    raise value.with_traceback(tb)
  File "/Users/shaquillewyanque/git/microblog/app/templates/email/reset_password.txt", line 5, in top-level template code
    {{ url_for('reset_password', token=token, _external=True) }}
  File "/Users/shaquillewyanque/git/microblog/venv/lib/python3.7/site-packages/flask/helpers.py", line 356, in url_for
    return appctx.app.handle_url_build_error(error, endpoint, values)
  File "/Users/shaquillewyanque/git/microblog/venv/lib/python3.7/site-packages/flask/app.py", line 2061, in handle_url_build_error
    reraise(exc_type, exc_value, tb)
  File "/Users/shaquillewyanque/git/microblog/venv/lib/python3.7/site-packages/flask/_compat.py", line 35, in reraise
    raise value
  File "/Users/shaquillewyanque/git/microblog/venv/lib/python3.7/site-packages/flask/helpers.py", line 345, in url_for
    force_external=external)
  File "/Users/shaquillewyanque/git/microblog/venv/lib/python3.7/site-packages/werkzeug/routing.py", line 1776, in build
    raise BuildError(endpoint, values, method, self)
werkzeug.routing.BuildError: Could not build url for endpoint 'reset_password' with values ['token']. Did you mean 'reset_password_request' instead?
2019-03-13 20:21:41,528 INFO: Microblog startup [in /Users/shaquillewyanque/git/microblog/app/__init__.py:45]
2019-03-13 20:21:47,326 ERROR: Exception on /reset_password_request [POST] [in /Users/shaquillewyanque/git/microblog/venv/lib/python3.7/site-packages/flask/app.py:1761]
Traceback (most recent call last):
  File "/Users/shaquillewyanque/git/microblog/venv/lib/python3.7/site-packages/flask/app.py", line 2292, in wsgi_app
    response = self.full_dispatch_request()
  File "/Users/shaquillewyanque/git/microblog/venv/lib/python3.7/site-packages/flask/app.py", line 1815, in full_dispatch_request
    rv = self.handle_user_exception(e)
  File "/Users/shaquillewyanque/git/microblog/venv/lib/python3.7/site-packages/flask/app.py", line 1718, in handle_user_exception
    reraise(exc_type, exc_value, tb)
  File "/Users/shaquillewyanque/git/microblog/venv/lib/python3.7/site-packages/flask/_compat.py", line 35, in reraise
    raise value
  File "/Users/shaquillewyanque/git/microblog/venv/lib/python3.7/site-packages/flask/app.py", line 1813, in full_dispatch_request
    rv = self.dispatch_request()
  File "/Users/shaquillewyanque/git/microblog/venv/lib/python3.7/site-packages/flask/app.py", line 1799, in dispatch_request
    return self.view_functions[rule.endpoint](**req.view_args)
  File "/Users/shaquillewyanque/git/microblog/app/routes.py", line 141, in reset_password_request
    send_password_reset_email(user)
  File "/Users/shaquillewyanque/git/microblog/app/email.py", line 17, in send_password_reset_email
    html_body=render_template('email/reset_password.html', user=user, token=token))
  File "/Users/shaquillewyanque/git/microblog/app/email.py", line 9, in send_email
    mail.send(msg)
  File "/Users/shaquillewyanque/git/microblog/venv/lib/python3.7/site-packages/flask_mail.py", line 491, in send
    with self.connect() as connection:
  File "/Users/shaquillewyanque/git/microblog/venv/lib/python3.7/site-packages/flask_mail.py", line 144, in __enter__
    self.host = self.configure_host()
  File "/Users/shaquillewyanque/git/microblog/venv/lib/python3.7/site-packages/flask_mail.py", line 158, in configure_host
    host = smtplib.SMTP(self.mail.server, self.mail.port)
  File "/usr/local/Cellar/python/3.7.2_1/Frameworks/Python.framework/Versions/3.7/lib/python3.7/smtplib.py", line 251, in __init__
    (code, msg) = self.connect(host, port)
  File "/usr/local/Cellar/python/3.7.2_1/Frameworks/Python.framework/Versions/3.7/lib/python3.7/smtplib.py", line 336, in connect
    self.sock = self._get_socket(host, port, self.timeout)
  File "/usr/local/Cellar/python/3.7.2_1/Frameworks/Python.framework/Versions/3.7/lib/python3.7/smtplib.py", line 307, in _get_socket
    self.source_address)
  File "/usr/local/Cellar/python/3.7.2_1/Frameworks/Python.framework/Versions/3.7/lib/python3.7/socket.py", line 727, in create_connection
    raise err
  File "/usr/local/Cellar/python/3.7.2_1/Frameworks/Python.framework/Versions/3.7/lib/python3.7/socket.py", line 716, in create_connection
    sock.connect(sa)
ConnectionRefusedError: [Errno 61] Connection refused
2019-03-13 20:24:57,552 INFO: Microblog startup [in /Users/shaquillewyanque/git/microblog/app/__init__.py:45]
2019-03-13 20:25:05,417 ERROR: Exception on /reset_password_request [POST] [in /Users/shaquillewyanque/git/microblog/venv/lib/python3.7/site-packages/flask/app.py:1761]
Traceback (most recent call last):
  File "/Users/shaquillewyanque/git/microblog/venv/lib/python3.7/site-packages/flask/app.py", line 2292, in wsgi_app
    response = self.full_dispatch_request()
  File "/Users/shaquillewyanque/git/microblog/venv/lib/python3.7/site-packages/flask/app.py", line 1815, in full_dispatch_request
    rv = self.handle_user_exception(e)
  File "/Users/shaquillewyanque/git/microblog/venv/lib/python3.7/site-packages/flask/app.py", line 1718, in handle_user_exception
    reraise(exc_type, exc_value, tb)
  File "/Users/shaquillewyanque/git/microblog/venv/lib/python3.7/site-packages/flask/_compat.py", line 35, in reraise
    raise value
  File "/Users/shaquillewyanque/git/microblog/venv/lib/python3.7/site-packages/flask/app.py", line 1813, in full_dispatch_request
    rv = self.dispatch_request()
  File "/Users/shaquillewyanque/git/microblog/venv/lib/python3.7/site-packages/flask/app.py", line 1799, in dispatch_request
    return self.view_functions[rule.endpoint](**req.view_args)
  File "/Users/shaquillewyanque/git/microblog/app/routes.py", line 141, in reset_password_request
    send_password_reset_email(user)
  File "/Users/shaquillewyanque/git/microblog/app/email.py", line 17, in send_password_reset_email
    html_body=render_template('email/reset_password.html', user=user, token=token))
  File "/Users/shaquillewyanque/git/microblog/app/email.py", line 9, in send_email
    mail.send(msg)
  File "/Users/shaquillewyanque/git/microblog/venv/lib/python3.7/site-packages/flask_mail.py", line 491, in send
    with self.connect() as connection:
  File "/Users/shaquillewyanque/git/microblog/venv/lib/python3.7/site-packages/flask_mail.py", line 144, in __enter__
    self.host = self.configure_host()
  File "/Users/shaquillewyanque/git/microblog/venv/lib/python3.7/site-packages/flask_mail.py", line 165, in configure_host
    host.login(self.mail.username, self.mail.password)
  File "/usr/local/Cellar/python/3.7.2_1/Frameworks/Python.framework/Versions/3.7/lib/python3.7/smtplib.py", line 697, in login
    "SMTP AUTH extension not supported by server.")
smtplib.SMTPNotSupportedError: SMTP AUTH extension not supported by server.
2019-03-13 23:44:09,786 INFO: Microblog startup [in /Users/shaquillewyanque/git/microblog/app/__init__.py:45]
